2020-01-20 17:16:56,561 ERROR: Exception on /user/john [GET] [in /Users/aliya/.local/share/virtualenvs/flask-tutorial-9-r7p8DH/lib/python3.7/site-packages/flask/app.py:1891]
Traceback (most recent call last):
  File "/Users/aliya/.local/share/virtualenvs/flask-tutorial-9-r7p8DH/lib/python3.7/site-packages/flask/app.py", line 2446, in wsgi_app
    response = self.full_dispatch_request()
  File "/Users/aliya/.local/share/virtualenvs/flask-tutorial-9-r7p8DH/lib/python3.7/site-packages/flask/app.py", line 1951, in full_dispatch_request
    rv = self.handle_user_exception(e)
  File "/Users/aliya/.local/share/virtualenvs/flask-tutorial-9-r7p8DH/lib/python3.7/site-packages/flask/app.py", line 1820, in handle_user_exception
    reraise(exc_type, exc_value, tb)
  File "/Users/aliya/.local/share/virtualenvs/flask-tutorial-9-r7p8DH/lib/python3.7/site-packages/flask/_compat.py", line 39, in reraise
    raise value
  File "/Users/aliya/.local/share/virtualenvs/flask-tutorial-9-r7p8DH/lib/python3.7/site-packages/flask/app.py", line 1949, in full_dispatch_request
    rv = self.dispatch_request()
  File "/Users/aliya/.local/share/virtualenvs/flask-tutorial-9-r7p8DH/lib/python3.7/site-packages/flask/app.py", line 1935, in dispatch_request
    return self.view_functions[rule.endpoint](**req.view_args)
  File "/Users/aliya/.local/share/virtualenvs/flask-tutorial-9-r7p8DH/lib/python3.7/site-packages/flask_login/utils.py", line 261, in decorated_view
    return func(*args, **kwargs)
  File "/Users/aliya/code-stuff/non-school-code/flask-tutorial/app/routes.py", line 70, in user
    return render_template('user.html', user=user, posts=posts)
  File "/Users/aliya/.local/share/virtualenvs/flask-tutorial-9-r7p8DH/lib/python3.7/site-packages/flask/templating.py", line 140, in render_template
    ctx.app,
  File "/Users/aliya/.local/share/virtualenvs/flask-tutorial-9-r7p8DH/lib/python3.7/site-packages/flask/templating.py", line 120, in _render
    rv = template.render(context)
  File "/Users/aliya/.local/share/virtualenvs/flask-tutorial-9-r7p8DH/lib/python3.7/site-packages/jinja2/asyncsupport.py", line 76, in render
    return original_render(self, *args, **kwargs)
  File "/Users/aliya/.local/share/virtualenvs/flask-tutorial-9-r7p8DH/lib/python3.7/site-packages/jinja2/environment.py", line 1008, in render
    return self.environment.handle_exception(exc_info, True)
  File "/Users/aliya/.local/share/virtualenvs/flask-tutorial-9-r7p8DH/lib/python3.7/site-packages/jinja2/environment.py", line 780, in handle_exception
    reraise(exc_type, exc_value, tb)
  File "/Users/aliya/.local/share/virtualenvs/flask-tutorial-9-r7p8DH/lib/python3.7/site-packages/jinja2/_compat.py", line 37, in reraise
    raise value.with_traceback(tb)
  File "/Users/aliya/code-stuff/non-school-code/flask-tutorial/app/templates/user.html", line 1, in top-level template code
    {% extends "base.html" %}
  File "/Users/aliya/.local/share/virtualenvs/flask-tutorial-9-r7p8DH/lib/python3.7/site-packages/jinja2/environment.py", line 1005, in render
    return concat(self.root_render_func(self.new_context(vars)))
  File "/Users/aliya/code-stuff/non-school-code/flask-tutorial/app/templates/user.html", line 14, in root
    <p>{{ user.followers.count() }} followers, {{ user.followed.count() }} following.</p>
  File "/Users/aliya/code-stuff/non-school-code/flask-tutorial/app/templates/base.html", line 54, in root
  File "/Users/aliya/code-stuff/non-school-code/flask-tutorial/app/templates/user.html", line 58, in block_content
  File "/Users/aliya/.local/share/virtualenvs/flask-tutorial-9-r7p8DH/lib/python3.7/site-packages/jinja2/runtime.py", line 262, in call
    return __obj(*args, **kwargs)
  File "/Users/aliya/.local/share/virtualenvs/flask-tutorial-9-r7p8DH/lib/python3.7/site-packages/flask/helpers.py", line 370, in url_for
    return appctx.app.handle_url_build_error(error, endpoint, values)
  File "/Users/aliya/.local/share/virtualenvs/flask-tutorial-9-r7p8DH/lib/python3.7/site-packages/flask/app.py", line 2215, in handle_url_build_error
    reraise(exc_type, exc_value, tb)
  File "/Users/aliya/.local/share/virtualenvs/flask-tutorial-9-r7p8DH/lib/python3.7/site-packages/flask/_compat.py", line 39, in reraise
    raise value
  File "/Users/aliya/.local/share/virtualenvs/flask-tutorial-9-r7p8DH/lib/python3.7/site-packages/flask/helpers.py", line 358, in url_for
    endpoint, values, method=method, force_external=external
  File "/Users/aliya/.local/share/virtualenvs/flask-tutorial-9-r7p8DH/lib/python3.7/site-packages/werkzeug/routing.py", line 2020, in build
    raise BuildError(endpoint, values, method, self)
werkzeug.routing.BuildError: Could not build url for endpoint 'follow' with values ['username']. Did you mean 'login' instead?
2020-01-20 17:17:52,697 ERROR: Exception on /user/susan [GET] [in /Users/aliya/.local/share/virtualenvs/flask-tutorial-9-r7p8DH/lib/python3.7/site-packages/flask/app.py:1891]
Traceback (most recent call last):
  File "/Users/aliya/.local/share/virtualenvs/flask-tutorial-9-r7p8DH/lib/python3.7/site-packages/flask/app.py", line 2446, in wsgi_app
    response = self.full_dispatch_request()
  File "/Users/aliya/.local/share/virtualenvs/flask-tutorial-9-r7p8DH/lib/python3.7/site-packages/flask/app.py", line 1951, in full_dispatch_request
    rv = self.handle_user_exception(e)
  File "/Users/aliya/.local/share/virtualenvs/flask-tutorial-9-r7p8DH/lib/python3.7/site-packages/flask/app.py", line 1820, in handle_user_exception
    reraise(exc_type, exc_value, tb)
  File "/Users/aliya/.local/share/virtualenvs/flask-tutorial-9-r7p8DH/lib/python3.7/site-packages/flask/_compat.py", line 39, in reraise
    raise value
  File "/Users/aliya/.local/share/virtualenvs/flask-tutorial-9-r7p8DH/lib/python3.7/site-packages/flask/app.py", line 1949, in full_dispatch_request
    rv = self.dispatch_request()
  File "/Users/aliya/.local/share/virtualenvs/flask-tutorial-9-r7p8DH/lib/python3.7/site-packages/flask/app.py", line 1935, in dispatch_request
    return self.view_functions[rule.endpoint](**req.view_args)
  File "/Users/aliya/.local/share/virtualenvs/flask-tutorial-9-r7p8DH/lib/python3.7/site-packages/flask_login/utils.py", line 261, in decorated_view
    return func(*args, **kwargs)
  File "/Users/aliya/code-stuff/non-school-code/flask-tutorial/app/routes.py", line 70, in user
    return render_template('user.html', user=user, posts=posts)
  File "/Users/aliya/.local/share/virtualenvs/flask-tutorial-9-r7p8DH/lib/python3.7/site-packages/flask/templating.py", line 140, in render_template
    ctx.app,
  File "/Users/aliya/.local/share/virtualenvs/flask-tutorial-9-r7p8DH/lib/python3.7/site-packages/flask/templating.py", line 120, in _render
    rv = template.render(context)
  File "/Users/aliya/.local/share/virtualenvs/flask-tutorial-9-r7p8DH/lib/python3.7/site-packages/jinja2/asyncsupport.py", line 76, in render
    return original_render(self, *args, **kwargs)
  File "/Users/aliya/.local/share/virtualenvs/flask-tutorial-9-r7p8DH/lib/python3.7/site-packages/jinja2/environment.py", line 1008, in render
    return self.environment.handle_exception(exc_info, True)
  File "/Users/aliya/.local/share/virtualenvs/flask-tutorial-9-r7p8DH/lib/python3.7/site-packages/jinja2/environment.py", line 780, in handle_exception
    reraise(exc_type, exc_value, tb)
  File "/Users/aliya/.local/share/virtualenvs/flask-tutorial-9-r7p8DH/lib/python3.7/site-packages/jinja2/_compat.py", line 37, in reraise
    raise value.with_traceback(tb)
  File "/Users/aliya/code-stuff/non-school-code/flask-tutorial/app/templates/user.html", line 1, in top-level template code
    {% extends "base.html" %}
  File "/Users/aliya/.local/share/virtualenvs/flask-tutorial-9-r7p8DH/lib/python3.7/site-packages/jinja2/environment.py", line 1005, in render
    return concat(self.root_render_func(self.new_context(vars)))
  File "/Users/aliya/code-stuff/non-school-code/flask-tutorial/app/templates/user.html", line 14, in root
    <p>{{ user.followers.count() }} followers, {{ user.followed.count() }} following.</p>
  File "/Users/aliya/code-stuff/non-school-code/flask-tutorial/app/templates/base.html", line 54, in root
  File "/Users/aliya/code-stuff/non-school-code/flask-tutorial/app/templates/user.html", line 58, in block_content
  File "/Users/aliya/.local/share/virtualenvs/flask-tutorial-9-r7p8DH/lib/python3.7/site-packages/jinja2/runtime.py", line 262, in call
    return __obj(*args, **kwargs)
  File "/Users/aliya/.local/share/virtualenvs/flask-tutorial-9-r7p8DH/lib/python3.7/site-packages/flask/helpers.py", line 370, in url_for
    return appctx.app.handle_url_build_error(error, endpoint, values)
  File "/Users/aliya/.local/share/virtualenvs/flask-tutorial-9-r7p8DH/lib/python3.7/site-packages/flask/app.py", line 2215, in handle_url_build_error
    reraise(exc_type, exc_value, tb)
  File "/Users/aliya/.local/share/virtualenvs/flask-tutorial-9-r7p8DH/lib/python3.7/site-packages/flask/_compat.py", line 39, in reraise
    raise value
  File "/Users/aliya/.local/share/virtualenvs/flask-tutorial-9-r7p8DH/lib/python3.7/site-packages/flask/helpers.py", line 358, in url_for
    endpoint, values, method=method, force_external=external
  File "/Users/aliya/.local/share/virtualenvs/flask-tutorial-9-r7p8DH/lib/python3.7/site-packages/werkzeug/routing.py", line 2020, in build
    raise BuildError(endpoint, values, method, self)
werkzeug.routing.BuildError: Could not build url for endpoint 'follow' with values ['username']. Did you mean 'login' instead?
2020-01-20 17:18:19,826 INFO: Microblog startup [in /Users/aliya/code-stuff/non-school-code/flask-tutorial/app/__init__.py:44]
